<mujoco model="chin">
  <compiler angle="radian" meshdir="assets" autolimits="true"/>

  <option gravity="0 0 -9.81"/>

  <default>
    <default class="chin">
      <joint armature="0.1" damping="1"/>
    </default>
  </default>
    
  <asset>
    <mesh name="link0" file="link0.STL" />
    <mesh name="link1" file="link1.STL" />
    <mesh name="link2" file="link2.STL" />
    <mesh name="link3" file="link3.STL" />
    <mesh name="link4" file="link4.STL" />
    <mesh name="link5" file="link5.STL" />
    <mesh name="link6" file="link6.STL" />
  </asset>
    
  <worldbody>
    <body name="link0" childclass="chin">
      <geom type="mesh" contype="0" conaffinity="0" group="1" rgba="1 1 1 1" mesh="link0" />
      <geom type="mesh" rgba="1 1 1 1" mesh="link0" />
      <body name="link1" pos="0 0 0.283" quat="0 1 0 0">
        <inertial pos="0 0.043 0.005" quat="1 0 0.000434518 0" mass="5.675" diaginertia="1.1632 1.1632 0.0124991"/>
        <joint name="joint1" pos="0 0 0" axis="0 0 1" limited="true" range="-3.05 3.05" />
        <!--geom type="mesh" contype="0" conaffinity="0" group="1" rgba="1 1 1 1" mesh="link1" /-->
        <geom type="mesh" rgba="1 1 1 1" mesh="link1" />
        <body name="link2" pos="0 0 0" quat="0.5 0.5 -0.5 0.5">
          <inertial pos="-0.298 0 -0.126" quat="0.47932 0.47932 0.519858 0.519858" mass="5.466" diaginertia="0.124731 0.122 0.0132685" />
          <joint name="joint2" pos="0 0 0" axis="0 0 1" limited="true" range="-3.05 3.05" />
          <!--geom type="mesh" contype="0" conaffinity="0" group="1" rgba="1 1 1 1" mesh="link2" /-->
          <geom type="mesh" rgba="1 1 1 1" mesh="link2" />
          <body name="link3" pos="-0.4 0 0" quat="0 1 0 0">
            <inertial pos="-0.274 0 -0.061" quat="0.464528 0.464528 0.533117 0.533117" mass="4.294" diaginertia="0.0823816 0.076 0.00861843" />
            <joint name="joint3" pos="0 0 0" axis="0 0 1" limited="true" range="-3.05 3.05" />
            <!--geom type="mesh" contype="0" conaffinity="0" group="1" rgba="1 1 1 1" mesh="link3" /-->
            <geom type="mesh" rgba="1 1 1 1" mesh="link3" />
            <body name="link4" pos="-0.36 0 0.19875" quat="0 0.707107 0.707107 0">
              <inertial pos="0 -0.055 0.001" quat="0.707107 0.707107 0 0" mass="2.732" diaginertia="0.005 0.005 0.003" />
              <joint name="joint4" pos="0 0 0" axis="0 0 1" limited="true" range="-3.05 3.05" />
              <!--geom type="mesh" contype="0" conaffinity="0" group="1" rgba="1 1 1 1" mesh="link4" /-->
              <geom type="mesh" rgba="1 1 1 1" mesh="link4" />
              <body name="link5" pos="0 -0.16975 0" quat="0.707107 -0.707107 0 0">
                <inertial pos="0 0.055 0.001" quat="0.707107 0.707107 0 0" mass="2.732" diaginertia="0.005 0.005 0.003" />
                <joint name="joint5" pos="0 0 0" axis="0 0 1" limited="true" range="-3.05 3.05" />
                <!--geom type="mesh" contype="0" conaffinity="0" group="1" rgba="1 1 1 1" mesh="link5" /-->
                <geom type="mesh" rgba="1 1 1 1" mesh="link5" />
                <body name="link6" pos="0 0.14875 0" quat="0.707107 0.707107 0 0">
                  <inertial pos="0 0 0.017" mass="0.28" diaginertia="0.01 0.01 0.01" />
                  <joint name="joint6" pos="0 0 0" axis="0 0 1" limited="true" range="-3.05 3.05" />
                  <!--geom type="mesh" contype="0" conaffinity="0" group="1" rgba="1 1 1 1" mesh="link6" /-->
                  <geom type="mesh" rgba="1 1 1 1" mesh="link6" />
                </body>
              </body>
            </body>
          </body>
        </body>
      </body>
    </body>
  </worldbody>
    
  <actuator>
    <general class="chin" name="actuator1" joint="joint1" ctrlrange="-200 200"/>
    <general class="chin" name="actuator2" joint="joint2" ctrlrange="-100 100"/>
    <general class="chin" name="actuator3" joint="joint3" ctrlrange="-100 100"/>
    <general class="chin" name="actuator4" joint="joint4" ctrlrange="-50 50"/>
    <general class="chin" name="actuator5" joint="joint5" ctrlrange="-50 50"/>
    <general class="chin" name="actuator6" joint="joint6" ctrlrange="-50 50"/>
  </actuator>
    
</mujoco>